Workbook

Sheet Cover
A1: Component list
A2: AGV I-PRIME driverless towing vehicle · DRAFT for TÜV SÜD preliminary review · not for production
A4: Product | B4: AGV I-PRIME driverless towing vehicle | D4: How to read and fill in
A5: Manufacturer | B5: PT INTI GANDA PERDANA, Jl Pegangsaan Dua Km 1.6, Jakarta Utara, Indonesia | D5: «…» | E5: Missing value. Edit these cells: replace the whole «…» text with the value.
A6: Document | B6: Component list (parts list, IEC 61355-1 kind &PB) | D6: [verify] / [confirm] / [decide] | E6: Filled, but not yet checked. Check it, then remove the flag (or the cell comment) and the colour.
A7: Document number | B7: «DOC-NO» | D7: PROPOSED | E7: Part should exist but is not yet on the circuit diagrams. Tag proposed; draw it, then set Status to "Drawn".
A8: Revision | B8: A | D8: Grey cell | E8: Formula. Do not type over it.
A9: Date | B9: 2026-11-01 | D9: Example row | E9: Devices row +EB-KE1 (FX3-CPU000000) is complete and shows the expected format.
A10: Created | B10: JOY M. | D10: Sources | E10: S-numbers point to sheet "Sources". Add a source whenever you fill a value.
A11: Checked | B11: JOKI I. | D11: Safety-related | E11: Y = part of a safety function SF1–SF5 (circuit diagram page 12). [decide] = for the risk assessment.
A12: Approved | B12: ROBERTA A. | D12: Safety functions | E12: SF1 emergency stop · SF2 personnel detection, front · SF4 mode selection · SF5 reset. SF3 (rear detection) is not fitted in this revision.
A13: Status | B13: DRAFT: for TÜV SÜD preliminary review, not for production
A14: Language | B14: English
A15: Related documents | B15: Circuit diagram «DOC-NO» (Rev. A, parts list on page 80) · Operation manual «DOC-NO» · Safety controller configuration report «DOC-NO»
A16: Rules applied | B16: IEC 62027:2011 (object and parts lists) · IEC 81346-1:2022 / IEC 81346-2:2019 (reference designations) · IEC 61355-1 (document kind) · ISO 13849-1:2023 clause 10 (safety data) · EN 1175:2025 (electrical installation)
A17: Scope | B17: Every electrical device on the vehicle, one row per occurrence, in the same tags as the circuit diagrams; safety data of the safety-related devices; cables; safety-relevant mechanical parts. Not included: off-board equipment (charger, tablet, Wi-Fi access point).
A19: Summary
A20: Device rows | B20: =COUNTA(Devices!D5:D200) -> 41
A21: Safety-related device rows (Y) | B21: =COUNTIF(Devices!M5:M200,"Y") -> 10
A22: Rows proposed, not yet on the circuit diagrams | B22: =COUNTIF(Devices!O5:O200,"PROPOSED*") -> 5
A23: Cells still to fill «…» (Devices) | B23: =SUMPRODUCT(--ISNUMBER(SEARCH("«",Devices!A5:Q200))) -> 92
A24: Cells still to fill «…» (Safety data) | B24: =SUMPRODUCT(--ISNUMBER(SEARCH("«",'Safety data'!A5:P200))) -> 22
A25: Open questions | B25: =COUNTA('Open questions'!B5:B200) -> 16
A27: Revisions
A28: Revision | B28: Change | D28: Date | E28: Name
A29: A | B29: First issue, draft | D29: 2026-11-01 | E29: JOY M.

Sheet Devices
A1: Devices: one row per occurrence, by reference designation (IEC 62027, IEC 81346)
A2: Same tags, locations and page numbers as the circuit diagrams. Accessories and built-in parts share the tag of the device they belong to.
A4: Item | B4: Group | C4: Location | D4: Tag | E4: Reference designation | F4: Old name (JIS sheets) | G4: Description | H4: Manufacturer | I4: Type designation | J4: Order no. | K4: Technical data | L4: Circuit diagram pages | M4: Safety-related | N4: Safety function(s) | O4: Status | P4: Sources | Q4: Remarks
A5: 1 | B5: Power | C5: +BT | D5: -GB1 | E5: =IF(D5="","",C5&D5) -> +BT-GB1 | F5: BATTERY | G5: Battery 48 V with battery management system (BMS on CAN) | H5: «MAKER» | I5: «TYPE» | J5: «ORDER NO» | K5: 48 V DC nominal, «chemistry», «Ah». The vehicle warns below 42 V and above 56 V | L5: 20, 51 | M5: N | O5: Drawn | P5: S1, S10 | Q5: BMS CAN link is drawn on page 51, but the as-built CAN node list has only the drivers and the line sensor (S3) [confirm]
A6: 2 | B6: Power | C6: +EB | D6: -QA1 | E6: =IF(D6="","",C6&D6) -> +EB-QA1 | F6: MCB-01 | G6: Circuit breaker, 2-pole: supply disconnecting device (main switch) | H6: «MAKER» | I6: «TYPE» | J6: «ORDER NO» | K6: 2P, 32 A, DC-rated, breaking capacity «kA» at «V» DC | L6: 20 | M6: N | O6: Drawn | P6: S1, S2 | Q6: Locked off for maintenance (operation manual 15.1)
A7: 3 | B7: Power | C7: +EB | D7: -QA1 | E7: =IF(D7="","",C7&D7) -> +EB-QA1 | G7: Accessory of -QA1: lock-out device (padlock attachment) | H7: «MAKER» | I7: «TYPE» | J7: «ORDER NO» | K7: To suit -QA1 | L7: — | M7: N | O7: PROPOSED: not yet on the circuit diagrams | P7: S2 | Q7: Designation map: "lockable handle [confirm]". Part of -QA1, so no tag of its own
A8: 4 | B8: Power | C8: +EB | D8: -FC1 | E8: =IF(D8="","",C8&D8) -> +EB-FC1 | F8: MCB-02 | G8: Circuit breaker, 1-pole: feeder, left motor driver (2P48) | H8: «MAKER» | I8: «TYPE» | J8: «ORDER NO» | K8: 1P, 10 A, DC-rated | L8: 20 | M8: N | O8: Drawn | P8: S1, S2
A9: 5 | B9: Power | C9: +EB | D9: -FC2 | E9: =IF(D9="","",C9&D9) -> +EB-FC2 | F9: MCB-03 | G9: Circuit breaker, 1-pole: feeder, right motor driver (3P48) | H9: «MAKER» | I9: «TYPE» | J9: «ORDER NO» | K9: 1P, 10 A, DC-rated | L9: 20 | M9: N | O9: Drawn | P9: S1, S2
A10: 6 | B10: Power | C10: +EB | D10: -FC3 | E10: =IF(D10="","",C10&D10) -> +EB-FC3 | F10: MCB-04 | G10: Circuit breaker, 2-pole: 24 V control bus (1P24) | H10: «MAKER» | I10: «TYPE» | J10: «ORDER NO» | K10: 2P, 10 A, DC-rated | L10: 30 | M10: N | O10: Drawn | P10: S1, S2 | Q10: Feeds -KE1, which needs its supply limited to 4 A (open question 1)
A11: 7 | B11: Power | C11: +EB | D11: -FC4 | E11: =IF(D11="","",C11&D11) -> +EB-FC4 | F11: MCB-05 | G11: Circuit breaker, 2-pole: 12 V bus (1P12) | H11: «MAKER» | I11: «TYPE» | J11: «ORDER NO» | K11: 2P, 10 A, DC-rated | L11: 32 | M11: N | O11: Drawn | P11: S1, S2
A12: 8 | B12: Power | C12: +EB | D12: -TA3 | E12: =IF(D12="","",C12&D12) -> +EB-TA3 | F12: BUCK01 | G12: DC/DC converter 48 → 24 V, isolated; supplies the safety controller | H12: Mean Well | I12: SD-150C-24 [confirm on label] | J12: Same as type | K12: In 36–72 V DC; out 24 V DC, 6.3 A (151 W); I/O isolation 1.5 kV AC | L12: 20, 30 | M12: N | O12: Drawn | P12: S1, S13 | Q12: The repo marks the type "?SD-150C-24". Its failure behaviour matters to the risk assessment (S2)
A13: 9 | B13: Power | C13: +EB | D13: -TA4 | E13: =IF(D13="","",C13&D13) -> +EB-TA4 | F13: BUCK02 | G13: DC/DC converter 48 → 12 V, isolated | H13: Mean Well | I13: «TYPE» | J13: «ORDER NO» | K13: Out 12 V DC, 8.3 A (100 W), per the circuit diagram | L13: 20, 32 | M13: N | O13: Drawn | P13: S1
A14: 10 | B14: Drives | C14: +EB | D14: -TA1 | E14: =IF(D14="","",C14&D14) -> +EB-TA1 | F14: DRIVER 01 | G14: Motor driver, left: brushless DC, CANopen, safe torque off (HWTO) with EDM output | H14: Oriental Motor | I14: BLVD-KRD | J14: Same as type | K14: 24–48 V DC in; for 400 W BLV-R motor; CANopen CiA 301 / 402; STO input 12–30 V DC; ambient 0–40 °C | L14: 21, 42, 50, 51 | M14: Y | N14: SF1, SF2 | O14: Drawn | P14: S1, S4, S5, S6, S12 | Q14: CANopen node 1 (S3). Factory STO jumpers removed. Safety data: sheet "Safety data"
A15: 11 | B15: Drives | C15: +EB | D15: -TA2 | E15: =IF(D15="","",C15&D15) -> +EB-TA2 | F15: DRIVER 02 | G15: Motor driver, right: brushless DC, CANopen, safe torque off (HWTO) with EDM output | H15: Oriental Motor | I15: BLVD-KRD | J15: Same as type | K15: 24–48 V DC in; for 400 W BLV-R motor; CANopen CiA 301 / 402; STO input 12–30 V DC; ambient 0–40 °C | L15: 21, 42, 50, 51 | M15: Y | N15: SF1, SF2 | O15: Drawn | P15: S1, S4, S5, S6, S12 | Q15: CANopen node 2 (S3)
A16: 12 | B16: Drives | C16: +VH | D16: -MA1 | E16: =IF(D16="","",C16&D16) -> +VH-MA1 | F16: LEFT MOTOR | G16: Brushless motor with electromagnetic holding brake, for parallel-shaft gearhead, left | H16: Oriental Motor | I16: BLMR6400SKM-GFV-B | J16: Same as type | K16: 400 W; holding brake released by -TA1 | L16: 21 | M16: [decide] | O16: Drawn | P16: S1, S5, S6 | Q16: Whether the brake counts in the stop function is a risk-assessment decision (S2). Gearhead: sheet "Mechanical"
A17: 13 | B17: Drives | C17: +VH | D17: -MA2 | E17: =IF(D17="","",C17&D17) -> +VH-MA2 | F17: RIGHT MOTOR | G17: Brushless motor with electromagnetic holding brake, for parallel-shaft gearhead, right | H17: Oriental Motor | I17: BLMR6400SKM-GFV-B | J17: Same as type | K17: 400 W; holding brake released by -TA2 | L17: 21 | M17: [decide] | O17: Drawn | P17: S1, S5, S6 | Q17: As -MA1
A18: 14 | B18: Safety | C18: +EB | D18: -KE1 | E18: =IF(D18="","",C18&D18) -> +EB-KE1 | F18: SAFETY PLC (CPU MODULE) | G18: Safety controller main module, Flexi Soft | H18: SICK | I18: FX3-CPU000000 | J18: 1043783 | K18: 24 V DC (16.8–30 V DC), PELV / SELV; supply current limited to 4 A max.; IP20; −25 to +55 °C | L18: 43 | M18: Y | N18: SF1, SF2, SF4, SF5 | O18: Drawn | P18: S1, S7 | Q18: Example of a complete row. The circuit diagrams call it "FX3-CPU0"
A19: 15 | B19: Safety | C19: +EB | D19: -KE1 | E19: =IF(D19="","",C19&D19) -> +EB-KE1 | G19: Accessory of -KE1: system plug (holds the safety configuration) | H19: SICK | I19: FX3-MPL000001 [confirm] | J19: 1043700 | K19: — | L19: 43 | M19: Y | N19: SF1, SF2, SF4, SF5 | O19: PROPOSED: not yet on the circuit diagrams | P19: S7 | Q19: SICK: "the system plug has to be ordered separately". Page 43 shows it as part of -KE1. Read the fitted type
A20: 16 | B20: Safety | C20: +EB | D20: -KE2 | E20: =IF(D20="","",C20&D20) -> +EB-KE2 | F20: SAFETY PLC (XTIO MODULE) | G20: Safety I/O module, Flexi Soft: 8 safe inputs, 2 test outputs, 4 safe outputs | H20: SICK | I20: FX3-XTIO84002 | J20: 1044125 | K20: 24 V DC (16.8–30 V DC); outputs PNP, short-circuit protected; IP20; −25 to +55 °C | L20: 40–44 | M20: Y | N20: SF1, SF2, SF4, SF5 | O20: Drawn | P20: S1, S8 | Q20: Q3, Q4 spare
A21: 17 | B21: Safety | C21: +FR | D21: -SJ1 | E21: =IF(D21="","",C21&D21) -> +FR-SJ1 | F21: EMERGENCY STOP PB | G21: Emergency stop push-button, 2 NC (11-12, 21-22), positive opening, turn to release | H21: «MAKER» | I21: «TYPE» | J21: «ORDER NO» | K21: Must meet ISO 13850 and IEC 60947-5-5 [confirm on the data sheet] | L21: 40 | M21: Y | N21: SF1 | O21: Drawn | P21: S1, S2 | Q21: To -KE2 I1 / I2, test pulses X1 / X2
A22: 18 | B22: Safety | C22: +FR | D22: -SJ3 | E22: =IF(D22="","",C22&D22) -> +FR-SJ3 | F22: PB RESET | G22: Push-button RESET, blue, 2 NO (13-14 → -KE2:I8; 23-24 → -KE4:DI01) | H22: «MAKER» | I22: «TYPE» | J22: «ORDER NO» | K22: 2 NO | L22: 40, 60 | M22: Y | N22: SF5 | O22: Drawn | P22: S1, S2
A23: 19 | B23: Safety | C23: +FR | D23: -SJ4 | E23: =IF(D23="","",C23&D23) -> +FR-SJ4 | F23: SS MANUAL/AUTO | G23: Selector switch MANUAL / AUTO, 2 positions, 2 NO (13-14 → -KE2:I7; 23-24 → -KE4:DI02) | H23: «MAKER» | I23: «TYPE» | J23: «ORDER NO» | K23: 2 positions, 2 NO | L23: 40, 60 | M23: Y | N23: SF4 | O23: Drawn | P23: S1, S2 | Q23: Which position closes the contacts is still open (S2)
A24: 20 | B24: Safety | C24: +VH | D24: -BG1 | E24: =IF(D24="","",C24&D24) -> +VH-BG1 | F24: SAFETY LIDAR 01 | G24: Safety laser scanner, front | H24: SICK | I24: nanoScan3 Core I/O «variant, e.g. NANS3-AAAZ30AN1» | J24: «ORDER NO, e.g. 1100333» | K24: Type 3 (IEC 61496); 24 V DC (16.8–30 V DC); 1 OSSD pair; IP65; measured data via Ethernet (values for NANS3-AAAZ30AN1) | L24: 30, 41 | M24: Y | N24: SF2 | O24: Drawn | P24: S1, S3, S9 | Q24: Core I/O inferred from the wiring: 1 OSSD pair to -KE2 I5 / I6, Ethernet data to -KE3 (192.168.3.10). Range variant not verified
A25: 21 | B25: Safety | C25: +VH | D25: -BG1 | E25: =IF(D25="","",C25&D25) -> +VH-BG1 | G25: Accessory of -BG1: system plug (connection unit) | H25: SICK | I25: «TYPE» | J25: «ORDER NO» | K25: — | L25: 41 | M25: Y | N25: SF2 | O25: PROPOSED: not yet on the circuit diagrams | P25: S9 | Q25: The data sheet lists the scanner "without system plug"; the connection type depends on the plug
A26: 22 | B26: Control | C26: +EB | D26: -KE3 | E26: =IF(D26="","",C26&D26) -> +EB-KE3 | F26: IPC | G26: Vehicle controller: fanless industrial PC, Intel N97 | H26: NEXCOM | I26: Neu-X102-N97 | J26: «ORDER NO» | K26: 12 V DC in; 2 × Ethernet (Intel i226); Wi-Fi; −5 to +50 °C (distributor data) [verify] | L26: 11, 32, 51 | M26: N | O26: Drawn | P26: S1, S3, S14 | Q26: Not safety-rated. LAN1 → -KE4 → -BG4; LAN2 → -BG1 (S3)
A27: 23 | B27: Control | C27: +EB | D27: -KE3 | E27: =IF(D27="","",C27&D27) -> +EB-KE3 | G27: Built into -KE3: Wi-Fi card (radio equipment) | H27: Intel | I27: Wireless 7260 | J27: — | K27: «bands, transmit power» | L27: 11 | M27: N | O27: Built into -KE3 | P27: S3 | Q27: Radio device: check Indonesian type approval (open question 11)
A28: 24 | B28: Control | C28: +EB | D28: -KE4 | E28: =IF(D28="","",C28&D28) -> +EB-KE4 | F28: DIGITAL IO | G28: I/O module: 16 DI / 12 relay DO, Modbus TCP, 2 Ethernet ports (IN / OUT) | H28: «MAKER» | I28: CK-EC5163 | J28: «ORDER NO» | K28: 24 V DC | L28: 30, 60–62 | M28: N | O28: Drawn | P28: S1, S3 | Q28: 192.168.1.30, Modbus TCP 502. Maker not identified; no public data sheet found
A29: 25 | B29: Control | C29: +EB | D29: -TF1 | E29: =IF(D29="","",C29&D29) -> +EB-TF1 | F29: CAN-USB ADAPTER | G29: USB-to-CAN interface (slcan firmware), on an IPC USB port | H29: Openlight Labs | I29: CANable 2.0 | J29: «ORDER NO» | K29: USB-powered; on-board 120 Ω termination, switchable; used at 125 kbit/s | L29: 11, 51 | M29: N | O29: Drawn | P29: S1, S3, S16 | Q29: USB ID 16d0:117e. Its termination closes one bus end (page 51 note 3)
A30: 26 | B30: Control | C30: +FR | D30: -SJ2 | E30: =IF(D30="","",C30&D30) -> +FR-SJ2 | F30: PB START | G30: Push-button START, 1 NO → -KE4:DI00 | H30: «MAKER» | I30: «TYPE» | J30: «ORDER NO» | K30: 1 NO, colour «colour» | L30: 60 | M30: N | O30: Drawn | P30: S1, S2
A31: 27 | B31: Control | C31: +FR | D31: -SJ5 | E31: =IF(D31="","",C31&D31) -> +FR-SJ5 | F31: MANUAL ARM SW | G31: Switch MANUAL ARM → -KE4:DI08 | H31: «MAKER» | I31: «TYPE» | J31: «ORDER NO» | K31: «switch type» | L31: 60 | M31: N | O31: Drawn | P31: S1, S2 | Q31: Location +FR [confirm]
A32: 28 | B32: Control | C32: +PD | D32: -SJ6 | E32: =IF(D32="","",C32&D32) -> +PD-SJ6 | F32: PENDANT FORWARD | G32: Pendant button FORWARD, 1 NO, hold to run → -KE4:DI03 | H32: «MAKER» | I32: «TYPE» | J32: «ORDER NO» | K32: 1 NO | L32: 60 | M32: N | O32: Drawn | P32: S1, S2
A33: 29 | B33: Control | C33: +PD | D33: -SJ7 | E33: =IF(D33="","",C33&D33) -> +PD-SJ7 | F33: PENDANT REVERSE | G33: Pendant button REVERSE, 1 NO, hold to run → -KE4:DI04 | H33: «MAKER» | I33: «TYPE» | J33: «ORDER NO» | K33: 1 NO | L33: 60 | M33: N | O33: Drawn | P33: S1, S2
A34: 30 | B34: Control | C34: +PD | D34: -SJ8 | E34: =IF(D34="","",C34&D34) -> +PD-SJ8 | F34: PENDANT LEFT | G34: Pendant button LEFT, 1 NO, hold to run → -KE4:DI05 | H34: «MAKER» | I34: «TYPE» | J34: «ORDER NO» | K34: 1 NO | L34: 60 | M34: N | O34: Drawn | P34: S1, S2
A35: 31 | B35: Control | C35: +PD | D35: -SJ9 | E35: =IF(D35="","",C35&D35) -> +PD-SJ9 | F35: PENDANT RIGHT | G35: Pendant button RIGHT, 1 NO, hold to run → -KE4:DI06 | H35: «MAKER» | I35: «TYPE» | J35: «ORDER NO» | K35: 1 NO | L35: 60 | M35: N | O35: Drawn | P35: S1, S2 | Q35: Common return on one wire
A36: 32 | B36: Sensors | C36: +VH | D36: -BG3 | E36: =IF(D36="","",C36&D36) -> +VH-BG3 | F36: LINE SENSOR 01 | G36: Magnetic line sensor, 200 mm, CANopen, with built-in IMU (gyro, accelerometer) | H36: SICK | I36: MLSE-0200 «full type code, e.g. MLSE-0200A2NP0» | J36: «ORDER NO» | K36: 24 V DC from 1P24; reads ±100 mm; CANopen node 10, 125 kbit/s | L36: 31, 51 | M36: N | O36: Drawn | P36: S1, S3, S11, S15 | Q36: The full type code tells whether a CAN terminator is built in (open question 6)
A37: 33 | B37: Sensors | C37: +VH | D37: -BG4 | E37: =IF(D37="","",C37&D37) -> +VH-BG4 | F37: RFID READER | G37: UHF RFID reader (EPC Gen2), Ethernet | H37: Chafon | I37: CF821 (module CP-203910_V1.13 / RN370MU-910) | J37: «ORDER NO» | K37: 12 V DC; set to 902.75–927.25 MHz (US region), 30 dBm | L37: 11, 32 | M37: N | O37: Drawn | P37: S1, S3 | Q37: Radio device. 192.168.1.200. Change to the Indonesian band 920–923 MHz is pending (open question 11)
A38: 34 | B38: Other | C38: +VH | D38: -PJ1 | E38: =IF(D38="","",C38&D38) -> +VH-PJ1 | F38: AUDIO HORN 01 | G38: Audio horn, 2 sounds: sound 1 = movement (DO0), sound 2 = alarm (DO1) | H38: PATLITE | I38: «TYPE» | J38: «ORDER NO» | K38: 24 V DC; «dB(A) at 1 m» | L38: 30, 61 | M38: N | O38: Drawn | P38: S1, S2, S10 | Q38: Software-driven warning device. Location +VH [confirm]
A39: 35 | B39: Other | C39: +FR | D39: -PH1 | E39: =IF(D39="","",C39&D39) -> +FR-PH1 | F39: DISPLAY | G39: Display: operator kiosk pages | H39: «MAKER» | I39: «TYPE» | J39: «ORDER NO» | K39: 24 V DC, barrel jack; «size» | L39: 31 | M39: N | O39: Drawn | P39: S1, S2, S3 | Q39: Location +FR [confirm]
A40: 36 | B40: Other | C40: +EB | D40: -GQ1 | E40: =IF(D40="","",C40&D40) -> +EB-GQ1 | F40: FAN 01 | G40: Fan, electrical box | H40: NMB-MAT | I40: «TYPE» | J40: «ORDER NO» | K40: 24 V DC | L40: 31 | M40: N | O40: Drawn | P40: S1, S2
A41: 37 | B41: Other | C41: +EB | D41: -GQ2 | E41: =IF(D41="","",C41&D41) -> +EB-GQ2 | F41: FAN 02 | G41: Fan, electrical box | H41: NMB-MAT | I41: «TYPE» | J41: «ORDER NO» | K41: 24 V DC | L41: 31 | M41: N | O41: Drawn | P41: S1, S2
...

Sheet Safety data
A1: Safety data of the safety-related devices (ISO 13849-1 clause 10)
A2: Values as stated by the component maker. Achieved PL and PFHd of each safety function come from the validation (SISTEMA), not from this list.
A4: Reference designation | B4: Device (from Devices) | C4: Manufacturer (from Devices) | D4: Type (from Devices) | E4: Safety function(s) | F4: Role in the function | G4: Type (IEC 61496) | H4: SIL (IEC 61508) | I4: PL (ISO 13849-1) | J4: Category | K4: PFHd [1/h] | L4: B10d [cycles] | M4: Mission time TM [years] | N4: Certificate (body, number, validity) | O4: Sources | P4: Remarks
A5: +EB-KE1 | B5: =IFERROR(INDEX(Devices!$G:$G,MATCH($A5,Devices!$E:$E,0)),"«not in Devices»") -> Safety controller main module, Flexi Soft | C5: =IFERROR(INDEX(Devices!$H:$H,MATCH($A5,Devices!$E:$E,0)),"«not in Devices»") -> SICK | D5: =IFERROR(INDEX(Devices!$I:$I,MATCH($A5,Devices!$E:$E,0)),"«not in Devices»") -> FX3-CPU000000 | E5: SF1, SF2, SF4, SF5 | F5: Logic | G5: — | H5: SIL 3 | I5: PL e | J5: Cat. 4 | K5: 1.07e-09 | L5: — | M5: 20 | N5: «body, number, validity» (check sick.com/1043783) | O5: S7 | P5: Data sheet copy dated 2024-11-27
A6: +EB-KE2 | B6: =IFERROR(INDEX(Devices!$G:$G,MATCH($A6,Devices!$E:$E,0)),"«not in Devices»") -> Safety I/O module, Flexi Soft: 8 safe inputs, 2 test outputs, 4 safe outputs | C6: =IFERROR(INDEX(Devices!$H:$H,MATCH($A6,Devices!$E:$E,0)),"«not in Devices»") -> SICK | D6: =IFERROR(INDEX(Devices!$I:$I,MATCH($A6,Devices!$E:$E,0)),"«not in Devices»") -> FX3-XTIO84002 | E6: SF1, SF2, SF4, SF5 | F6: Logic (safe inputs and outputs) | G6: — | H6: SIL 3 | I6: PL e | J6: Cat. 4 | K6: 4.8e-09 | L6: — | M6: 20 | N6: Data sheet lists EC-type examination (Directive and Machinery Regulation), UK-type examination, cULus, S Mark. «body, number, validity» | O6: S8 | P6: PFHd 4.8 × 10⁻⁹ for single-channel outputs, 0.9 × 10⁻⁹ for dual-channel outputs: use the value that matches the configured outputs Q1 / Q2
A7: +VH-BG1 | B7: =IFERROR(INDEX(Devices!$G:$G,MATCH($A7,Devices!$E:$E,0)),"«not in Devices»") -> Safety laser scanner, front | C7: =IFERROR(INDEX(Devices!$H:$H,MATCH($A7,Devices!$E:$E,0)),"«not in Devices»") -> SICK | D7: =IFERROR(INDEX(Devices!$I:$I,MATCH($A7,Devices!$E:$E,0)),"«not in Devices»") -> nanoScan3 Core I/O «variant, e.g. NANS3-AAAZ30AN1» | E7: SF2 | F7: Input (sensor) | G7: Type 3 | H7: SIL 2 | I7: PL d | J7: Cat. 3 | K7: 8e-08 | L7: — | M7: 20 | N7: Data sheet lists EC-type examination (Directive and Machinery Regulation), UK-type examination, cULus, S Mark, China GB. «body, number, validity» | O7: S9 | P7: Values for NANS3-AAAZ30AN1: confirm the fitted variant. Basic response time 70 ms on the data sheet; the configured value comes from the Safety Designer report
A8: +EB-TA1 | B8: =IFERROR(INDEX(Devices!$G:$G,MATCH($A8,Devices!$E:$E,0)),"«not in Devices»") -> Motor driver, left: brushless DC, CANopen, safe torque off (HWTO) with EDM output | C8: =IFERROR(INDEX(Devices!$H:$H,MATCH($A8,Devices!$E:$E,0)),"«not in Devices»") -> Oriental Motor | D8: =IFERROR(INDEX(Devices!$I:$I,MATCH($A8,Devices!$E:$E,0)),"«not in Devices»") -> BLVD-KRD | E8: SF1, SF2 | F8: Output (STO) | G8: — | H8: SIL 2 | I8: PL d | J8: Cat. 3 | K8: 2.9e-07 | L8: — | M8: «TM» | N8: TÜV SÜD Product Service GmbH, Z10 106467 0002 Rev. 00, valid until 2029-08-12 (test report OT102914T). Tested to IEC 61800-5-2:2016, IEC 61508-1/-2:2010 (SIL 2), ISO 13849-1:2023 (Cat. 3, PL d) | O8: S4, S5, S10 | P8: STO input 12–30 V DC. EDM output to -KE2 I3
A9: +EB-TA2 | B9: =IFERROR(INDEX(Devices!$G:$G,MATCH($A9,Devices!$E:$E,0)),"«not in Devices»") -> Motor driver, right: brushless DC, CANopen, safe torque off (HWTO) with EDM output | C9: =IFERROR(INDEX(Devices!$H:$H,MATCH($A9,Devices!$E:$E,0)),"«not in Devices»") -> Oriental Motor | D9: =IFERROR(INDEX(Devices!$I:$I,MATCH($A9,Devices!$E:$E,0)),"«not in Devices»") -> BLVD-KRD | E9: SF1, SF2 | F9: Output (STO) | G9: — | H9: SIL 2 | I9: PL d | J9: Cat. 3 | K9: 2.9e-07 | L9: — | M9: «TM» | N9: TÜV SÜD Product Service GmbH, Z10 106467 0002 Rev. 00, valid until 2029-08-12 (test report OT102914T). Tested to IEC 61800-5-2:2016, IEC 61508-1/-2:2010 (SIL 2), ISO 13849-1:2023 (Cat. 3, PL d) | O9: S4, S5, S10 | P9: EDM output to -KE2 I4
A10: +FR-SJ1 | B10: =IFERROR(INDEX(Devices!$G:$G,MATCH($A10,Devices!$E:$E,0)),"«not in Devices»") -> Emergency stop push-button, 2 NC (11-12, 21-22), positive opening, turn to release | C10: =IFERROR(INDEX(Devices!$H:$H,MATCH($A10,Devices!$E:$E,0)),"«not in Devices»") -> «MAKER» | D10: =IFERROR(INDEX(Devices!$I:$I,MATCH($A10,Devices!$E:$E,0)),"«not in Devices»") -> «TYPE» | E10: SF1 | F10: Input (command device) | G10: — | H10: — | I10: — | J10: — | K10: — | L10: 50000 | M10: «TM» | N10: «certificate, if any» | O10: S10 | P10: Maker and type not identified
A11: +FR-SJ3 | B11: =IFERROR(INDEX(Devices!$G:$G,MATCH($A11,Devices!$E:$E,0)),"«not in Devices»") -> Push-button RESET, blue, 2 NO (13-14 → -KE2:I8; 23-24 → -KE4:DI01) | C11: =IFERROR(INDEX(Devices!$H:$H,MATCH($A11,Devices!$E:$E,0)),"«not in Devices»") -> «MAKER» | D11: =IFERROR(INDEX(Devices!$I:$I,MATCH($A11,Devices!$E:$E,0)),"«not in Devices»") -> «TYPE» | E11: SF5 | F11: Input (reset) | G11: — | H11: — | I11: — | J11: — | K11: — | L11: «B10d» | M11: «TM» | N11: — | O11: S1
A12: +FR-SJ4 | B12: =IFERROR(INDEX(Devices!$G:$G,MATCH($A12,Devices!$E:$E,0)),"«not in Devices»") -> Selector switch MANUAL / AUTO, 2 positions, 2 NO (13-14 → -KE2:I7; 23-24 → -KE4:DI02) | C12: =IFERROR(INDEX(Devices!$H:$H,MATCH($A12,Devices!$E:$E,0)),"«not in Devices»") -> «MAKER» | D12: =IFERROR(INDEX(Devices!$I:$I,MATCH($A12,Devices!$E:$E,0)),"«not in Devices»") -> «TYPE» | E12: SF4 | F12: Input (mode selection) | G12: — | H12: — | I12: — | J12: — | K12: — | L12: «B10d» | M12: «TM» | N12: — | O12: S1
A13: +VH-MA1 | B13: =IFERROR(INDEX(Devices!$G:$G,MATCH($A13,Devices!$E:$E,0)),"«not in Devices»") -> Brushless motor with electromagnetic holding brake, for parallel-shaft gearhead, left | C13: =IFERROR(INDEX(Devices!$H:$H,MATCH($A13,Devices!$E:$E,0)),"«not in Devices»") -> Oriental Motor | D13: =IFERROR(INDEX(Devices!$I:$I,MATCH($A13,Devices!$E:$E,0)),"«not in Devices»") -> BLMR6400SKM-GFV-B | E13: [decide] | F13: Holding brake: holds the vehicle after STO | G13: — | H13: — | I13: — | J13: — | K13: — | L13: «B10d» | M13: «TM» | N13: — | O13: S2 | P13: Only if the risk assessment counts the brake in a safety function
A14: +VH-MA2 | B14: =IFERROR(INDEX(Devices!$G:$G,MATCH($A14,Devices!$E:$E,0)),"«not in Devices»") -> Brushless motor with electromagnetic holding brake, for parallel-shaft gearhead, right | C14: =IFERROR(INDEX(Devices!$H:$H,MATCH($A14,Devices!$E:$E,0)),"«not in Devices»") -> Oriental Motor | D14: =IFERROR(INDEX(Devices!$I:$I,MATCH($A14,Devices!$E:$E,0)),"«not in Devices»") -> BLMR6400SKM-GFV-B | E14: [decide] | F14: Holding brake: holds the vehicle after STO | G14: — | H14: — | I14: — | J14: — | K14: — | L14: «B10d» | M14: «TM» | N14: — | O14: S2 | P14: As -MA1

Sheet Mechanical
A1: Safety-relevant mechanical parts
A2: Not tagged on the circuit diagrams (designation map: mechanical parts are not tagged).
A4: Item | B4: Part | C4: Belongs to | D4: Manufacturer | E4: Type designation | F4: Qty | G4: Technical data | H4: Why it is safety-relevant | I4: Status | J4: Sources | K4: Remarks
A5: 1 | B5: Gearhead, parallel shaft, 1:30 | C5: +VH-MA1 | D5: Oriental Motor | E5: «TYPE, e.g. GFV6G30» [verify] | F5: 1 | G5: Ratio 1:30 | H5: Carries drive and holding-brake torque to the left wheel | I5: Fitted | J5: S1, S12 | K5: The type is inferred from Oriental Motor naming (GFV6G15 = 1:15); read the label
A6: 2 | B6: Gearhead, parallel shaft, 1:30 | C6: +VH-MA2 | D6: Oriental Motor | E6: «TYPE, e.g. GFV6G30» [verify] | F6: 1 | G6: Ratio 1:30 | H6: As left | I6: Fitted | J6: S1, S12 | K6: As left
A7: 3 | B7: Drive wheel | C7: +VH | D7: «MAKER» | E7: «TYPE» | F7: 2 | G7: Ø 180 mm; track width 487 mm; tread «material» | H7: Traction and braking: stopping distance depends on it | I7: Fitted | J7: S10
A8: 4 | B8: Castor | C8: +VH | D8: «MAKER» | E8: «TYPE» | F8: «qty» | G8: «wheel Ø, load rating» | H8: Stability | I8: [confirm] | J8: S10 | K8: The manual says "castors [confirm]"
A9: 5 | B9: Towing hitch | C9: +VH | D9: «MAKER or in-house» | E9: «pin or hook» [TBD] | F9: 1 | G9: Towed mass max. 1 000 kg; drawbar force est. ≈ 1 200 N [verify]; coupling height «mm» | H9: Uncoupling during travel; crushing at the coupling point | I9: Fitted | J9: S10 | K9: Operation manual 4.6
A10: 6 | B10: Hitch securing device | C10: Towing hitch | D10: «MAKER» | E10: «TYPE, e.g. spring cotter» [TBD] | F10: 1 | G10: — | H10: Stops the trolley uncoupling by itself | I10: [confirm] | J10: S10
A11: 7 | B11: Scanner mounting bracket | C11: +VH-BG1 | D11: «MAKER or in-house» | E11: «drawing no.» | F11: 1 | G11: Holds -BG1 0.964 m ahead of the axle, scan plane 110 mm above the floor | H11: The protective field is only valid at this position and height | I11: Fitted | J11: S18

Sheet Cables
A1: Cables (circuit diagram page 75)
A2: Colours: 48 V power black; 24 V / 12 V control and safety blue; PE green-and-yellow; supplier cables as supplied.
A4: Item | B4: Cable tag | C4: Manufacturer | D4: Type | E4: Cores × size | F4: From | G4: To | H4: Circuit diagram pages | I4: Length | J4: Sources | K4: Remarks
A5: 1 | B5: -WD1 | C5: «MAKER» | D5: NYAF single cores, black | E5: 2 × 4 mm² | F5: -GB1 | G5: -QA1 | H5: 20 | I5: «m» | J5: S1
A6: 2 | B6: -WD2 | C6: «MAKER» | D6: NYAF single cores, black | E6: 2 × 2.5 mm² | F6: -FC1, 1N48 bus | G6: -WD6 | H6: 21 | I6: «m» | J6: S1
A7: 3 | B7: -WD3 | C7: «MAKER» | D7: NYAF single cores, black | E7: 2 × 2.5 mm² | F7: -FC2, 1N48 bus | G7: -WD7 | H7: 21 | I7: «m» | J7: S1
A8: 4 | B8: -WD4 | C8: «MAKER» | D8: NYAF single cores, black | E8: 2 × 1.5 mm² | F8: 1P48, 1N48 | G8: -TA3 in | H8: 20 | I8: «m» | J8: S1
A9: 5 | B9: -WD5 | C9: «MAKER» | D9: NYAF single cores, black | E9: 2 × 1.5 mm² | F9: 1P48, 1N48 | G9: -TA4 in | H9: 20 | I9: «m» | J9: S1
A10: 6 | B10: -WD6 | C10: Oriental Motor | D10: LC03D06A | E10: 3 cores (+, 0 V, PE) | F10: -WD2, PE | G10: -TA1 power | H10: 21 | I10: «m» | J10: S1
A11: 7 | B11: -WD7 | C11: Oriental Motor | D11: LC03D06A | E11: 3 cores (+, 0 V, PE) | F11: -WD3, PE | G11: -TA2 power | H11: 21 | I11: «m» | J11: S1
A12: 8 | B12: -WD8 | C12: Oriental Motor | D12: CCM010B1AAF | E12: motor + encoder | F12: -TA1 | G12: -MA1 | H12: 21 | I12: 1 m | J12: S1
A13: 9 | B13: -WD9 | C13: Oriental Motor | D13: CCM010B1AAF | E13: motor + encoder | F13: -TA2 | G13: -MA2 | H13: 21 | I13: 1 m | J13: S1
A14: 10 | B14: -WD10 | C14: «MAKER» | D14: Display power cable | E14: 2 cores | F14: 1P24, 1N24 | G14: -PH1 | H14: 31 | I14: «m» | J14: S1
A15: 11 | B15: -WD11 | C15: «MAKER» | D15: IPC power cable | E15: 2 cores | F15: 1P12, 1N12 | G15: -KE3 | H15: 32 | I15: «m» | J15: S1
A16: 12 | B16: -WD12 | C16: «MAKER» | D16: RFID power cable | E16: 2 cores | F16: 1P12, 1N12 | G16: -BG4 | H16: 32 | I16: «m» | J16: S1
... A18: 14 | B18: -WG2 | C18: SICK | D18: MLSE power and communication cable «TYPE» | E18: «cores» | F18: 1P24, 1N24; CAN bus | G18: -BG3 | H18: 31, 51 | I18: «m» | J18: S1
A19: 15 | B19: -WG3 | C19: Belden | D19: 9841 (CAN H, L) + AWG22 core (GND) | E19: 1 × 2 × 0.32 mm² + 1 | F19: CAN bus | G19: -TA1:5, 6, 7 | H19: 51 | I19: «m» | J19: S1 | K19: Shield connection «confirm» (page 51 note 4)
A20: 16 | B20: -WG4 | C20: Belden | D20: 9841 (CAN H, L) + AWG22 core (GND) | E20: 1 × 2 × 0.32 mm² + 1 | F20: CAN bus | G20: -TA2:5, 6, 7 | H20: 51 | I20: «m» | J20: S1 | K20: Shield connection «confirm» (page 51 note 4)
A21: 17 | B21: -WG5 | C21: Belden | D21: 9841 + battery communication cable | E21: «cores» | F21: CAN bus | G21: -GB1 BMS | H21: 51 | I21: «m» | J21: S1
A22: 18 | B22: -WG6 | C22: «MAKER» | D22: USB cable | E22: USB | F22: -KE3 | G22: -TF1 | H22: 11, 51 | I22: «m» | J22: S1
A23: 19 | B23: -WG7 | C23: «MAKER» | D23: Ethernet patch cable | E23: RJ45 | F23: -KE3 LAN1 | G23: -KE4 IN | H23: 11 | I23: «m» | J23: S1 | K23: Circuit diagram data names the port enp2s0 (open question 10)
A24: 20 | B24: -WG8 | C24: «MAKER» | D24: Ethernet patch cable | E24: RJ45 | F24: -KE4 OUT | G24: -BG4 | H24: 11 | I24: «m» | J24: S1
A25: 21 | B25: -WG9 | C25: «MAKER» | D25: Ethernet cable (scanner data) | E25: M12 / RJ45 | F25: -KE3 LAN2 | G25: -BG1 | H25: 11, 41 | I25: «m» | J25: S1 | K25: Circuit diagram data names the port enp1s0; alpha-setup.md says enp3s0 (open question 10)
A26: 22 | B26: -WG10 | C26: «MAKER» | D26: Pendant cable | E26: «5 cores» | F26: -KE4:DI03–DI06, 1N24 | G26: +PD | H26: 60 | I26: «m» | J26: S1

Sheet Open questions
A1: Open questions found while building this list
A2: Close each one, then update the affected rows.
A4: No. | B4: Topic | C4: Question | D4: Affects | E4: Why it matters | F4: Status
A5: 1 | B5: Safety controller supply | C5: SICK requires the supply of the FX3-CPU0 main unit to be current-limited to 4 A max., by the power supply or a fuse (S7). -KE1 is fed from 1P24 behind -FC3 (10 A); -TA3 delivers 6.3 A. Page 43 shows no 4 A fuse. Add one, or show where the limit is. | D5: -KE1, -KE2, -TA3, -FC3 | E5: Condition of use of a safety component | F5: Open
A6: 2 | B6: nanoScan3 variant | C6: Read the type label and system plug of -BG1. The list assumes a Core I/O (1 OSSD pair, Ethernet data); the range variant is unknown. | D6: -BG1 | E6: Safety data and certificate depend on the variant | F6: Open
A7: 3 | B7: Scanner response time | C7: The data sheet gives 70 ms (basic, NANS3-AAAZ30AN1); the operation manual states 130 ms. Take the configured value from the Safety Designer report. | D7: -BG1 | E7: Protective field sizing and stopping distance | F7: Open
A8: 4 | B8: Driver PFHd | C8: PFHd 2.90 × 10⁻⁷ per driver is in the manual draft but not on the TÜV certificate on file. Get Oriental Motor's functional safety data (PFHd, mission time, conditions of use). | D8: -TA1, -TA2 | E8: SISTEMA input for SF1, SF2 | F8: Open
A9: 5 | B9: Command devices | C9: Maker, type and B10d of the E-stop, RESET and MANUAL/AUTO selector. The manual's B10d 50 000 for the E-stop has no maker source. | D9: -SJ1, -SJ3, -SJ4 | E9: SISTEMA input for SF1, SF4, SF5 | F9: Open
A10: 6 | B10: CAN far-end termination | C10: Which device terminates the far bus end? The MLSE type code shows whether an internal terminator is fitted (distributor listings: "…A2N…" = none [verify]); the drivers and the BMS may have one too. Check: H–L resistance with power off = 60 Ω (S17). | D10: -RA1, -BG3, -TA2, -GB1 | E10: Bus reliability | F10: Open
A11: 7 | B11: BMS on CAN | C11: Page 51 draws the BMS on the CAN bus, but the as-built node list (S3) has only nodes 1, 2 and 10. Is the BMS connected and read? | D11: -GB1, -WG5 | E11: Circuit diagram accuracy | F11: Open
A12: 8 | B12: CAN ground and the floating 48 V system | C12: CAN GND (-WG3, -WG4) joins the drivers' CAN ground to -TF1 and the IPC. Unless the driver CAN port or -TF1 is isolated, 1N48 may be joined to 1N12 / 1N24, contrary to the diagram note "48 V floating". Check the BLVD-KRD and CANable 2.0 data. | D12: -TA1, -TA2, -TF1, -KE3 | E12: Isolation claim on pages 10 and 20 | F12: Open
A13: 9 | B13: Battery | C13: Maker, type, chemistry, capacity. Is a main fuse fitted inside the pack? EN 1175:2025 battery requirements to be checked. | D13: -GB1 | E13: EN 1175 compliance | F13: Open
A14: 10 | B14: IPC port names | C14: alpha-setup.md (as built): LAN1 = enp2s0 → I/O module and RFID; LAN2 = enp3s0 → scanner. Circuit diagram data: enp1s0 → scanner. Confirm on the vehicle. | D14: -KE3, -WG7, -WG9 | E14: Circuit diagram accuracy | F14: Open
A15: 11 | B15: Radio equipment | C15: The RFID reader is set to the US band (902.75–927.25 MHz); Indonesia allows 920–923 MHz. Type approval (SDPPI) for the RFID reader and the Wi-Fi card. | D15: -BG4, -KE3 | E15: Legal use in Indonesia | F15: Open
A16: 12 | B16: Converter types | C16: -TA3 is marked "?SD-150C-24" in the repo; -TA4 type unknown. Read the labels. | D16: -TA3, -TA4 | F16: Open
A17: 13 | B17: Unknown makers and types | C17: Breakers, push-buttons, display, horn, fans, CK-EC5163 maker, cables marked «MAKER». | D17: see «» cells | E17: Completeness | F17: Open
A18: 14 | B18: Motor brake | C18: Does the holding brake count in a safety function (stop and hold)? | D18: -MA1, -MA2 | E18: Risk assessment | F18: Open
A19: 15 | B19: Mechanical | C19: Gearhead type code, castors, hitch type and securing device. | D19: sheet Mechanical | F19: Open
A20: 16 | B20: Proposed tags | C20: Draw -XD1 (charging socket) and -RA1 (CAN terminator, if discrete) on the circuit diagrams, and the -QA1 lock-out device, -KE1 and -BG1 system plugs in the parts list (page 80). | D20: -XD1, -RA1 | E20: List and diagrams must match | F20: Open

Sheet Sources
A1: Sources
A2: Repository paths are relative to the gvievo-01 repository root.
A4: ID | B4: What it gives | C4: Where
A5: S1 | B5: Circuit diagram data, Rev. A draft (devices, cables, safety I/O) | C5: documentation/electrical/01-schematic-iec/data/project.js; pages 43, 51
A6: S2 | B6: Designation map: JIS names → IEC 81346 tags | C6: documentation/electrical/01-schematic-iec/designation-map.md
A7: S3 | B7: As-built vehicle set-up guide (unit 1, 2026-09-21): IPC, CANable, RFID reader, network, CAN nodes | C7: alpha-setup.md
A8: S4 | B8: TÜV SÜD certificate Z10 106467 0002 Rev. 00, BLV Series R Type driver, STO | C8: manuals/certifications-compliance/TUVSUD_Z10_106467_0002.pdf
A9: S5 | B9: Oriental Motor declaration DoC-9205 (2025-04-01); appendix lists BLVD-KRD with BLMR6400SKM-GFV-B | C9: manuals/certifications-compliance/DoC-9205.pdf
A10: S6 | B10: UL certificates UL-CA-2122856-0 (BLVD-KRD) and UL-CA-2150278-0 (BLMR6400SKM…), to CSA C22.2 No. 62368-1 | C10: manuals/certifications-compliance/UL_E208200X4A6005.pdf, UL_E208200X5A6008.pdf
A11: S7 | B11: SICK data sheet FX3-CPU000000, dated 2024-11-27 (third-party copy; official page sick.com/1043783) | C11: https://www.motionworld.com/assets/SICK-FX3_CPU000000-Datasheet.pdf
A12: S8 | B12: SICK data sheet FX3-XTIO84002, dated 2026-10-29 | C12: https://www.sick.com/media/pdf/0/80/480/dataSheet_FX3-XTIO84002_1044125_en.pdf
A13: S9 | B13: SICK data sheet NANS3-AAAZ30AN1 (nanoScan3 Core I/O), dated 2026-10-23 | C13: https://www.sick.com/media/pdf/9/79/979/dataSheet_NANS3-AAAZ30AN1_1100333_en.pdf
A14: S10 | B14: Operation manual draft (2026-10-31): safety components, technical data 16.1, hitch 4.6, charging 12 | C14: documentation/operation-manual/operation-manual-doc.md
A15: S11 | B15: IMU inside the MLS; MLSE-0200 sensor | C15: agv_core/drivers/canbus/read_imu.py; manuals/mls-marker-plan.md
... A22: S18 | B22: Scanner position (0.964 m ahead of the axle, 0.110 m above the floor) | C22: amr_ws/src/amr_description/launch/description.launch.py
